2023-02-03 11:02:18,562 INFO    MainThread:845027 [internal.py:wandb_internal():89] W&B internal server running at pid: 845027, started at: 2023-02-03 11:02:18.562255
2023-02-03 11:02:18,564 DEBUG   HandlerThread:845027 [handler.py:handle_request():126] handle_request: check_version
2023-02-03 11:02:18,564 INFO    WriterThread:845027 [datastore.py:open_for_write():77] open: /home/22842219/Desktop/phd/SemanticParser4Graph/semantic_parser/wandb/run-20230203_110217-29faciio/run-29faciio.wandb
2023-02-03 11:02:18,565 DEBUG   SenderThread:845027 [sender.py:send():182] send: header
2023-02-03 11:02:18,566 DEBUG   SenderThread:845027 [sender.py:send_request():196] send_request: check_version
2023-02-03 11:02:19,023 DEBUG   SenderThread:845027 [sender.py:send():182] send: run
2023-02-03 11:02:19,490 ERROR   SenderThread:845027 [internal_api.py:execute():133] 404 response executing GraphQL.
2023-02-03 11:02:19,490 ERROR   SenderThread:845027 [internal_api.py:execute():134] {"errors":[{"message":"project not found","path":["upsertBucket"]}],"data":{"upsertBucket":null}}
2023-02-03 11:02:20,023 INFO    WriterThread:845027 [datastore.py:close():281] close: /home/22842219/Desktop/phd/SemanticParser4Graph/semantic_parser/wandb/run-20230203_110217-29faciio/run-29faciio.wandb
2023-02-03 11:02:20,024 INFO    HandlerThread:845027 [handler.py:finish():683] shutting down handler
2023-02-03 11:02:20,024 ERROR   MainThread:845027 [internal.py:wandb_internal():157] Thread SenderThread:
Traceback (most recent call last):
  File "/root/anaconda3/envs/py3.7pytorch1.8new/lib/python3.7/site-packages/wandb/sdk/lib/retry.py", line 102, in __call__
    result = self._call_fn(*args, **kwargs)
  File "/root/anaconda3/envs/py3.7pytorch1.8new/lib/python3.7/site-packages/wandb/sdk/internal/internal_api.py", line 136, in execute
    six.reraise(*sys.exc_info())
  File "/root/anaconda3/envs/py3.7pytorch1.8new/lib/python3.7/site-packages/six.py", line 703, in reraise
    raise value
  File "/root/anaconda3/envs/py3.7pytorch1.8new/lib/python3.7/site-packages/wandb/sdk/internal/internal_api.py", line 130, in execute
    return self.client.execute(*args, **kwargs)
  File "/root/anaconda3/envs/py3.7pytorch1.8new/lib/python3.7/site-packages/wandb/vendor/gql-0.2.0/gql/client.py", line 52, in execute
    result = self._get_result(document, *args, **kwargs)
  File "/root/anaconda3/envs/py3.7pytorch1.8new/lib/python3.7/site-packages/wandb/vendor/gql-0.2.0/gql/client.py", line 60, in _get_result
    return self.transport.execute(document, *args, **kwargs)
  File "/root/anaconda3/envs/py3.7pytorch1.8new/lib/python3.7/site-packages/wandb/vendor/gql-0.2.0/gql/transport/requests.py", line 39, in execute
    request.raise_for_status()
  File "/root/anaconda3/envs/py3.7pytorch1.8new/lib/python3.7/site-packages/requests/models.py", line 953, in raise_for_status
    raise HTTPError(http_error_msg, response=self)
requests.exceptions.HTTPError: 404 Client Error: Not Found for url: https://api.wandb.ai/graphql

During handling of the above exception, another exception occurred:

Traceback (most recent call last):
  File "/root/anaconda3/envs/py3.7pytorch1.8new/lib/python3.7/site-packages/wandb/apis/normalize.py", line 24, in wrapper
    return func(*args, **kwargs)
  File "/root/anaconda3/envs/py3.7pytorch1.8new/lib/python3.7/site-packages/wandb/sdk/internal/internal_api.py", line 1087, in upsert_run
    response = self.gql(mutation, variable_values=variable_values, **kwargs)
  File "/root/anaconda3/envs/py3.7pytorch1.8new/lib/python3.7/site-packages/wandb/sdk/lib/retry.py", line 118, in __call__
    if not check_retry_fn(e):
  File "/root/anaconda3/envs/py3.7pytorch1.8new/lib/python3.7/site-packages/wandb/util.py", line 809, in no_retry_auth
    raise CommError("Permission denied, ask the project owner to grant you access")
wandb.errors.CommError: Permission denied, ask the project owner to grant you access

During handling of the above exception, another exception occurred:

Traceback (most recent call last):
  File "/root/anaconda3/envs/py3.7pytorch1.8new/lib/python3.7/site-packages/wandb/sdk/internal/internal_util.py", line 52, in run
    self._run()
  File "/root/anaconda3/envs/py3.7pytorch1.8new/lib/python3.7/site-packages/wandb/sdk/internal/internal_util.py", line 102, in _run
    self._process(record)
  File "/root/anaconda3/envs/py3.7pytorch1.8new/lib/python3.7/site-packages/wandb/sdk/internal/internal.py", line 290, in _process
    self._sm.send(record)
  File "/root/anaconda3/envs/py3.7pytorch1.8new/lib/python3.7/site-packages/wandb/sdk/internal/sender.py", line 184, in send
    send_handler(record)
  File "/root/anaconda3/envs/py3.7pytorch1.8new/lib/python3.7/site-packages/wandb/sdk/internal/sender.py", line 623, in send_run
    self._init_run(run, config_value_dict)
  File "/root/anaconda3/envs/py3.7pytorch1.8new/lib/python3.7/site-packages/wandb/sdk/internal/sender.py", line 659, in _init_run
    commit=repo.last_commit,
  File "/root/anaconda3/envs/py3.7pytorch1.8new/lib/python3.7/site-packages/wandb/apis/normalize.py", line 62, in wrapper
    six.reraise(CommError, CommError(message, err), sys.exc_info()[2])
  File "/root/anaconda3/envs/py3.7pytorch1.8new/lib/python3.7/site-packages/six.py", line 702, in reraise
    raise value.with_traceback(tb)
  File "/root/anaconda3/envs/py3.7pytorch1.8new/lib/python3.7/site-packages/wandb/apis/normalize.py", line 24, in wrapper
    return func(*args, **kwargs)
  File "/root/anaconda3/envs/py3.7pytorch1.8new/lib/python3.7/site-packages/wandb/sdk/internal/internal_api.py", line 1087, in upsert_run
    response = self.gql(mutation, variable_values=variable_values, **kwargs)
  File "/root/anaconda3/envs/py3.7pytorch1.8new/lib/python3.7/site-packages/wandb/sdk/lib/retry.py", line 118, in __call__
    if not check_retry_fn(e):
  File "/root/anaconda3/envs/py3.7pytorch1.8new/lib/python3.7/site-packages/wandb/util.py", line 809, in no_retry_auth
    raise CommError("Permission denied, ask the project owner to grant you access")
wandb.errors.CommError: Permission denied, ask the project owner to grant you access
2023-02-03 11:02:22,105 INFO    MainThread:845027 [internal.py:handle_exit():76] Internal process exited
