2023-02-03 11:08:28,014 INFO    MainThread:845772 [wandb_setup.py:_flush():69] setting env: {'project': 'text-to-sql(text2cyphr_Feb)', 'api_key': 'edd277e1d782e96634109705a6235577032da246', 'entity': 'leamonzea929'}
2023-02-03 11:08:28,014 INFO    MainThread:845772 [wandb_setup.py:_flush():69] setting login settings: {}
2023-02-03 11:08:28,014 INFO    MainThread:845772 [wandb_init.py:_log_setup():342] Logging user logs to /home/22842219/Desktop/phd/SemanticParser4Graph/semantic_parser/wandb/run-20230203_110828-349699o6/logs/debug.log
2023-02-03 11:08:28,014 INFO    MainThread:845772 [wandb_init.py:_log_setup():343] Logging internal logs to /home/22842219/Desktop/phd/SemanticParser4Graph/semantic_parser/wandb/run-20230203_110828-349699o6/logs/debug-internal.log
2023-02-03 11:08:28,014 INFO    MainThread:845772 [wandb_init.py:init():375] calling init triggers
2023-02-03 11:08:28,014 INFO    MainThread:845772 [wandb_init.py:init():382] wandb.init called with sweep_config: {}
config: {}
2023-02-03 11:08:28,014 INFO    MainThread:845772 [wandb_init.py:init():424] starting backend
2023-02-03 11:08:28,015 INFO    MainThread:845772 [backend.py:_multiprocessing_setup():72] multiprocessing start_methods=fork,spawn,forkserver, using: spawn
2023-02-03 11:08:28,027 INFO    MainThread:845772 [backend.py:ensure_launched():135] starting backend process...
2023-02-03 11:08:28,036 INFO    MainThread:845772 [backend.py:ensure_launched():140] started backend process with pid: 845809
2023-02-03 11:08:28,037 INFO    MainThread:845772 [wandb_init.py:init():429] backend started and connected
2023-02-03 11:08:28,040 INFO    MainThread:845772 [wandb_init.py:init():477] updated telemetry
2023-02-03 11:08:28,041 INFO    MainThread:845772 [wandb_init.py:init():500] communicating current version
2023-02-03 11:08:28,679 INFO    MainThread:845772 [wandb_init.py:init():505] got version response upgrade_message: "wandb version 0.13.9 is available!  To upgrade, please run:\n $ pip install wandb --upgrade"

2023-02-03 11:08:28,680 INFO    MainThread:845772 [wandb_init.py:init():513] communicating run to backend with 30 second timeout
2023-02-03 11:08:42,471 ERROR   Thread-1  :845772 [internal_api.py:execute():133] 500 response executing GraphQL.
2023-02-03 11:08:42,472 ERROR   Thread-1  :845772 [internal_api.py:execute():134] {"error":"internal database error"}
2023-02-03 11:08:42,472 ERROR   Thread-1  :845772 [retry.py:__call__():126] Retry attempt failed:
Traceback (most recent call last):
  File "/root/anaconda3/envs/py3.7pytorch1.8new/lib/python3.7/site-packages/wandb/sdk/lib/retry.py", line 102, in __call__
    result = self._call_fn(*args, **kwargs)
  File "/root/anaconda3/envs/py3.7pytorch1.8new/lib/python3.7/site-packages/wandb/sdk/internal/internal_api.py", line 136, in execute
    six.reraise(*sys.exc_info())
  File "/root/anaconda3/envs/py3.7pytorch1.8new/lib/python3.7/site-packages/six.py", line 703, in reraise
    raise value
  File "/root/anaconda3/envs/py3.7pytorch1.8new/lib/python3.7/site-packages/wandb/sdk/internal/internal_api.py", line 130, in execute
    return self.client.execute(*args, **kwargs)
  File "/root/anaconda3/envs/py3.7pytorch1.8new/lib/python3.7/site-packages/wandb/vendor/gql-0.2.0/gql/client.py", line 52, in execute
    result = self._get_result(document, *args, **kwargs)
  File "/root/anaconda3/envs/py3.7pytorch1.8new/lib/python3.7/site-packages/wandb/vendor/gql-0.2.0/gql/client.py", line 60, in _get_result
    return self.transport.execute(document, *args, **kwargs)
  File "/root/anaconda3/envs/py3.7pytorch1.8new/lib/python3.7/site-packages/wandb/vendor/gql-0.2.0/gql/transport/requests.py", line 39, in execute
    request.raise_for_status()
  File "/root/anaconda3/envs/py3.7pytorch1.8new/lib/python3.7/site-packages/requests/models.py", line 953, in raise_for_status
    raise HTTPError(http_error_msg, response=self)
requests.exceptions.HTTPError: 500 Server Error: Internal Server Error for url: https://api.wandb.ai/graphql
2023-02-03 11:08:58,680 INFO    MainThread:845772 [interface.py:_communicate_run():651] couldn't get run from backend
2023-02-03 11:08:58,681 ERROR   MainThread:845772 [wandb_init.py:init():518] backend process timed out
2023-02-03 11:08:58,681 ERROR   MainThread:845772 [wandb_init.py:init():527] encountered error: Error communicating with wandb process
try: wandb.init(settings=wandb.Settings(start_method='fork'))
or:  wandb.init(settings=wandb.Settings(start_method='thread'))
For more info see: https://docs.wandb.ai/library/init#init-start-error
2023-02-03 11:09:05,627 ERROR   Thread-1  :845772 [internal_api.py:execute():133] 500 response executing GraphQL.
2023-02-03 11:09:05,642 ERROR   Thread-1  :845772 [internal_api.py:execute():134] {"error":"internal database error"}
2023-02-03 11:09:26,172 ERROR   Thread-1  :845772 [internal_api.py:execute():133] 500 response executing GraphQL.
2023-02-03 11:09:26,172 ERROR   Thread-1  :845772 [internal_api.py:execute():134] {"error":"internal database error"}
2023-02-03 11:13:55,599 INFO    MainThread:845772 [wandb_init.py:teardown():194] tearing down wandb.init
