2023-02-03 11:08:28,636 INFO    MainThread:845809 [internal.py:wandb_internal():89] W&B internal server running at pid: 845809, started at: 2023-02-03 11:08:28.635774
2023-02-03 11:08:28,637 DEBUG   HandlerThread:845809 [handler.py:handle_request():126] handle_request: check_version
2023-02-03 11:08:28,638 INFO    WriterThread:845809 [datastore.py:open_for_write():77] open: /home/22842219/Desktop/phd/SemanticParser4Graph/semantic_parser/wandb/run-20230203_110828-349699o6/run-349699o6.wandb
2023-02-03 11:08:28,639 DEBUG   SenderThread:845809 [sender.py:send():182] send: header
2023-02-03 11:08:28,639 DEBUG   SenderThread:845809 [sender.py:send_request():196] send_request: check_version
2023-02-03 11:08:28,681 DEBUG   SenderThread:845809 [sender.py:send():182] send: run
2023-02-03 11:08:29,478 ERROR   SenderThread:845809 [internal_api.py:execute():133] 500 response executing GraphQL.
2023-02-03 11:08:29,478 ERROR   SenderThread:845809 [internal_api.py:execute():134] {"error":"internal database error"}
2023-02-03 11:08:33,336 ERROR   SenderThread:845809 [internal_api.py:execute():133] 500 response executing GraphQL.
2023-02-03 11:08:33,337 ERROR   SenderThread:845809 [internal_api.py:execute():134] {"error":"internal database error"}
2023-02-03 11:08:38,741 ERROR   SenderThread:845809 [internal_api.py:execute():133] 500 response executing GraphQL.
2023-02-03 11:08:38,742 ERROR   SenderThread:845809 [internal_api.py:execute():134] {"errors":[{"message":"internal database error","path":["upsertBucket"]}],"data":{"upsertBucket":null}}
2023-02-03 11:08:38,743 ERROR   SenderThread:845809 [retry.py:__call__():126] Retry attempt failed:
Traceback (most recent call last):
  File "/root/anaconda3/envs/py3.7pytorch1.8new/lib/python3.7/site-packages/wandb/sdk/lib/retry.py", line 102, in __call__
    result = self._call_fn(*args, **kwargs)
  File "/root/anaconda3/envs/py3.7pytorch1.8new/lib/python3.7/site-packages/wandb/sdk/internal/internal_api.py", line 136, in execute
    six.reraise(*sys.exc_info())
  File "/root/anaconda3/envs/py3.7pytorch1.8new/lib/python3.7/site-packages/six.py", line 703, in reraise
    raise value
  File "/root/anaconda3/envs/py3.7pytorch1.8new/lib/python3.7/site-packages/wandb/sdk/internal/internal_api.py", line 130, in execute
    return self.client.execute(*args, **kwargs)
  File "/root/anaconda3/envs/py3.7pytorch1.8new/lib/python3.7/site-packages/wandb/vendor/gql-0.2.0/gql/client.py", line 52, in execute
    result = self._get_result(document, *args, **kwargs)
  File "/root/anaconda3/envs/py3.7pytorch1.8new/lib/python3.7/site-packages/wandb/vendor/gql-0.2.0/gql/client.py", line 60, in _get_result
    return self.transport.execute(document, *args, **kwargs)
  File "/root/anaconda3/envs/py3.7pytorch1.8new/lib/python3.7/site-packages/wandb/vendor/gql-0.2.0/gql/transport/requests.py", line 39, in execute
    request.raise_for_status()
  File "/root/anaconda3/envs/py3.7pytorch1.8new/lib/python3.7/site-packages/requests/models.py", line 953, in raise_for_status
    raise HTTPError(http_error_msg, response=self)
requests.exceptions.HTTPError: 500 Server Error: Internal Server Error for url: https://api.wandb.ai/graphql
2023-02-03 11:08:58,681 DEBUG   HandlerThread:845809 [handler.py:handle_request():126] handle_request: shutdown
2023-02-03 11:08:58,682 INFO    HandlerThread:845809 [handler.py:finish():683] shutting down handler
2023-02-03 11:08:58,686 INFO    WriterThread:845809 [datastore.py:close():281] close: /home/22842219/Desktop/phd/SemanticParser4Graph/semantic_parser/wandb/run-20230203_110828-349699o6/run-349699o6.wandb
2023-02-03 11:09:03,689 ERROR   SenderThread:845809 [internal_api.py:execute():133] 500 response executing GraphQL.
2023-02-03 11:09:03,690 ERROR   SenderThread:845809 [internal_api.py:execute():134] {"error":"internal database error"}
2023-02-03 11:09:29,490 ERROR   SenderThread:845809 [internal_api.py:execute():133] 500 response executing GraphQL.
2023-02-03 11:09:29,490 ERROR   SenderThread:845809 [internal_api.py:execute():134] {"errors":[{"message":"internal database error","path":["upsertBucket"]}],"data":{"upsertBucket":null}}
2023-02-03 11:10:02,776 ERROR   SenderThread:845809 [internal_api.py:execute():133] 500 response executing GraphQL.
2023-02-03 11:10:02,776 ERROR   SenderThread:845809 [internal_api.py:execute():134] {"error":"internal database error"}
2023-02-03 11:13:52,013 INFO    SenderThread:845809 [dir_watcher.py:__init__():169] watching files in: /home/22842219/Desktop/phd/SemanticParser4Graph/semantic_parser/wandb/run-20230203_110828-349699o6/files
2023-02-03 11:13:52,013 INFO    SenderThread:845809 [sender.py:_start_run_threads():743] run started: 349699o6 with start time 1675393708
2023-02-03 11:13:52,013 INFO    SenderThread:845809 [sender.py:finish():979] shutting down sender
2023-02-03 11:13:52,013 INFO    SenderThread:845809 [dir_watcher.py:finish():283] shutting down directory watcher
2023-02-03 11:13:53,014 INFO    SenderThread:845809 [dir_watcher.py:finish():313] scan: /home/22842219/Desktop/phd/SemanticParser4Graph/semantic_parser/wandb/run-20230203_110828-349699o6/files
2023-02-03 11:13:53,014 INFO    SenderThread:845809 [dir_watcher.py:finish():327] scan save: /home/22842219/Desktop/phd/SemanticParser4Graph/semantic_parser/wandb/run-20230203_110828-349699o6/files/config.yaml config.yaml
2023-02-03 11:13:53,024 INFO    SenderThread:845809 [file_pusher.py:finish():177] shutting down file pusher
2023-02-03 11:13:53,024 INFO    SenderThread:845809 [file_pusher.py:join():182] waiting for file pusher
2023-02-03 11:13:54,403 INFO    Thread-10 :845809 [upload_job.py:push():137] Uploaded file /home/22842219/Desktop/phd/SemanticParser4Graph/semantic_parser/wandb/run-20230203_110828-349699o6/files/config.yaml
2023-02-03 11:13:55,515 INFO    MainThread:845809 [internal.py:handle_exit():76] Internal process exited
